Workbook

Sheet README
A1: SIMM-style initial margin workbook (RatesFX: IR and FX delta, vega, curvature) with schedule IM, backtests and attribution.
A3: ALL DATA IS SYNTHETIC. This is a SIMM-style implementation for learning and validation practice. It is not ISDA licensed, not ISDA certified and makes no compliance claim. ISDA SIMM is a trademark of ISDA.
A5: How to use: change a value on Inputs (parameter set, exception probability, Basel probabilities) or a typed CRIF amount on Sensitivities, a notional or PV on Portfolio, or a loss or forecast on Backtest, and all live sheets recalculate. Checks!B3 equals 1 when every live cell matches the Python reference within tolerance (the references on Python_Ref belong to the shipped inputs, so Checks will show 0 once you change an input; that is expected).
A7: Sheets: Inputs and Parameters (typed, with provenance), Portfolio, Sensitivities (typed CRIF plus helper columns and closed-form Bachelier and Garman-Kohlhagen checks), SIMM_Delta, SIMM_Vega, SIMM_Curvature, SIMM_Total, Schedule_IM, Backtest, Attribution (live formulas), Checks, Conclusions (static text), Python_Ref (typed Python results), Parameters_Reg (typed schedule rates, weights and BCBS 22 Table 2).
A9: What is replicated in cell formulas: net sensitivities, risk weights by lookup, concentration risk CR, weighted sensitivities, 12x12 tenor correlation grids, K and S per currency, inter-currency aggregation with gamma and g_bc, FX sigma_SIMM, FX delta and vega with concentration scaling, curvature scale factors, theta, lambda, HVR scale, risk class and RatesFX aggregation, schedule IM, Kupiec, Christoffersen, Basel zone, Shapley and bridge.
A11: LIMITS, stated plainly. (1) The CRIF is typed from Python: trade pricing and the bump and reprice sensitivities are not replicated in Excel; only one swaption (Bachelier) and one FX option (Garman-Kohlhagen) are repriced in closed form as spot checks. (2) The sample CRIF has no inflation or cross-currency basis rows and a single OIS sub-curve, so those SIMM branches (inflation risk weight, basis correlation of minus 1 percent, sub-curve phi) are not built into the formulas. (3) The 16 subset IMs of the attribution are typed from Python because each needs a full SIMM run on a different market or portfolio. The rates, FX and vol split of the market step is typed for the same reason. (4) The Backtest series are typed because the VaR models need the full simulated history. (5) The workbook was recalculated and verified in LibreOffice only. It uses functions that Excel 2016 also has, but it was not opened in Excel.
A13: Shipped inputs: parameter set 2.8+2512, calculation currency USD, p = 0.010000000000000009.

Sheet Inputs
A1: Inputs (typed). Change a value here and the live sheets recalculate.
A4: SIMM parameter set | B4: 2.8+2512
A5: Calculation currency | B5: USD
A6: Exception probability p (1 minus confidence) | B6: 0.01
A7: Basel yellow zone cumulative probability | B7: 0.95
A8: Basel red zone cumulative probability | B8: 0.9999
A9: USD per million (thresholds are in USD mm) | B9: 1000000
A10: Basel window (observations) | B10: 250
A12: Lists used as labels by the live sheets
A13: IR currencies | B13: USD | C13: EUR | D13: GBP | E13: JPY | F13: MXN
A14: Tenor labels | B14: 2w | C14: 1m | D14: 3m | E14: 6m | F14: 1y | G14: 2y | H14: 3y | I14: 5y | J14: 10y | K14: 15y | L14: 20y | M14: 30y
A15: Tenor years | B15: 0.038356164 | C15: 0.083333333 | D15: 0.25 | E15: 0.5 | F15: 1 | G15: 2 | H15: 3 | I15: 5 | J15: 10 | K15: 15 | L15: 20 | M15: 30
A16: FX currencies | B16: EUR | C16: GBP | D16: JPY | E16: MXN
A17: FX pairs | B17: EURUSD | C17: GBPUSD | D17: USDJPY | E17: USDMXN
A19: Currency | B19: USD per unit (schedule IM notionals)
A20: USD | B20: 1
A21: EUR | B21: 1.08
A22: GBP | B22: 1.27
A23: JPY | B23: 0.0067567568
A24: MXN | B24: 0.055555556
A27: Case | B27: base

Sheet Parameters
A1: SIMM-style parameters (typed from data/parameters/simm_parameters.csv with provenance). Column A is the lookup key.
A4: key | B4: param_set | C4: risk_class | D4: param_name | E4: key1 | F4: key2 | G4: value | H4: unit | I4: source_doc | J4: version | K4: effective_date | L4: section | M4: paragraph | N4: table | O4: pdf_page | P4: source_url | Q4: retrieved_on | R4: source_sha256 | S4: verification_status | T4: verification_method
A5: =B5&"|"&C5&"|"&D5&"|"&E5&"|"&F5 -> 2.8+2512|IR|delta_rw|regular|2w | B5: 2.8+2512 | C5: IR | D5: delta_rw | E5: regular | F5: 2w | G5: 107 | H5: multiplier of per-1bp sensitivity | I5: ISDA SIMM Methodology v2.8+2512 (based on v2.8+2512.2, 13 May 2026) | J5: 2.8+2512 | K5: 2026-07-11 | L5: D.1 | M5: 33 | N5: Table 1 risk weights per vertex | O5: 14 | P5: https://www.isda.org/a/hhkiE/ISDA-SIMM_v2.82512_PUBLIC.pdf | Q5: 2026-10-02 | R5: 8484d3de7dcb5280b6ad6458d051c50f8ccc3370bc279ae1c47a7bccb8064636 | S5: VERIFIED_PRIMARY | T5: two extractors agree (PyMuPDF, markitdown; sequence) + page image check
A6: =B6&"|"&C6&"|"&D6&"|"&E6&"|"&F6 -> 2.8+2512|IR|delta_rw|regular|1m | B6: 2.8+2512 | C6: IR | D6: delta_rw | E6: regular | F6: 1m | G6: 101 | H6: multiplier of per-1bp sensitivity | I6: ISDA SIMM Methodology v2.8+2512 (based on v2.8+2512.2, 13 May 2026) | J6: 2.8+2512 | K6: 2026-07-11 | L6: D.1 | M6: 33 | N6: Table 1 risk weights per vertex | O6: 14 | P6: https://www.isda.org/a/hhkiE/ISDA-SIMM_v2.82512_PUBLIC.pdf | Q6: 2026-10-02 | R6: 8484d3de7dcb5280b6ad6458d051c50f8ccc3370bc279ae1c47a7bccb8064636 | S6: VERIFIED_PRIMARY | T6: two extractors agree (PyMuPDF, markitdown; sequence) + page image check
A7: =B7&"|"&C7&"|"&D7&"|"&E7&"|"&F7 -> 2.8+2512|IR|delta_rw|regular|3m | B7: 2.8+2512 | C7: IR | D7: delta_rw | E7: regular | F7: 3m | G7: 90 | H7: multiplier of per-1bp sensitivity | I7: ISDA SIMM Methodology v2.8+2512 (based on v2.8+2512.2, 13 May 2026) | J7: 2.8+2512 | K7: 2026-07-11 | L7: D.1 | M7: 33 | N7: Table 1 risk weights per vertex | O7: 14 | P7: https://www.isda.org/a/hhkiE/ISDA-SIMM_v2.82512_PUBLIC.pdf | Q7: 2026-10-02 | R7: 8484d3de7dcb5280b6ad6458d051c50f8ccc3370bc279ae1c47a7bccb8064636 | S7: VERIFIED_PRIMARY | T7: two extractors agree (PyMuPDF, markitdown; sequence) + page image check
A8: =B8&"|"&C8&"|"&D8&"|"&E8&"|"&F8 -> 2.8+2512|IR|delta_rw|regular|6m | B8: 2.8+2512 | C8: IR | D8: delta_rw | E8: regular | F8: 6m | G8: 69 | H8: multiplier of per-1bp sensitivity | I8: ISDA SIMM Methodology v2.8+2512 (based on v2.8+2512.2, 13 May 2026) | J8: 2.8+2512 | K8: 2026-07-11 | L8: D.1 | M8: 33 | N8: Table 1 risk weights per vertex | O8: 14 | P8: https://www.isda.org/a/hhkiE/ISDA-SIMM_v2.82512_PUBLIC.pdf | Q8: 2026-10-02 | R8: 8484d3de7dcb5280b6ad6458d051c50f8ccc3370bc279ae1c47a7bccb8064636 | S8: VERIFIED_PRIMARY | T8: two extractors agree (PyMuPDF, markitdown; sequence) + page image check
A9: =B9&"|"&C9&"|"&D9&"|"&E9&"|"&F9 -> 2.8+2512|IR|delta_rw|regular|1y | B9: 2.8+2512 | C9: IR | D9: delta_rw | E9: regular | F9: 1y | G9: 68 | H9: multiplier of per-1bp sensitivity | I9: ISDA SIMM Methodology v2.8+2512 (based on v2.8+2512.2, 13 May 2026) | J9: 2.8+2512 | K9: 2026-07-11 | L9: D.1 | M9: 33 | N9: Table 1 risk weights per vertex | O9: 14 | P9: https://www.isda.org/a/hhkiE/ISDA-SIMM_v2.82512_PUBLIC.pdf | Q9: 2026-10-02 | R9: 8484d3de7dcb5280b6ad6458d051c50f8ccc3370bc279ae1c47a7bccb8064636 | S9: VERIFIED_PRIMARY | T9: two extractors agree (PyMuPDF, markitdown; sequence) + page image check
A10: =B10&"|"&C10&"|"&D10&"|"&E10&"|"&F10 -> 2.8+2512|IR|delta_rw|regular|2y | B10: 2.8+2512 | C10: IR | D10: delta_rw | E10: regular | F10: 2y | G10: 69 | H10: multiplier of per-1bp sensitivity | I10: ISDA SIMM Methodology v2.8+2512 (based on v2.8+2512.2, 13 May 2026) | J10: 2.8+2512 | K10: 2026-07-11 | L10: D.1 | M10: 33 | N10: Table 1 risk weights per vertex | O10: 14 | P10: https://www.isda.org/a/hhkiE/ISDA-SIMM_v2.82512_PUBLIC.pdf | Q10: 2026-10-02 | R10: 8484d3de7dcb5280b6ad6458d051c50f8ccc3370bc279ae1c47a7bccb8064636 | S10: VERIFIED_PRIMARY | T10: two extractors agree (PyMuPDF, markitdown; sequence) + page image check
A11: =B11&"|"&C11&"|"&D11&"|"&E11&"|"&F11 -> 2.8+2512|IR|delta_rw|regular|3y | B11: 2.8+2512 | C11: IR | D11: delta_rw | E11: regular | F11: 3y | G11: 66 | H11: multiplier of per-1bp sensitivity | I11: ISDA SIMM Methodology v2.8+2512 (based on v2.8+2512.2, 13 May 2026) | J11: 2.8+2512 | K11: 2026-07-11 | L11: D.1 | M11: 33 | N11: Table 1 risk weights per vertex | O11: 14 | P11: https://www.isda.org/a/hhkiE/ISDA-SIMM_v2.82512_PUBLIC.pdf | Q11: 2026-10-02 | R11: 8484d3de7dcb5280b6ad6458d051c50f8ccc3370bc279ae1c47a7bccb8064636 | S11: VERIFIED_PRIMARY | T11: two extractors agree (PyMuPDF, markitdown; sequence) + page image check
A12: =B12&"|"&C12&"|"&D12&"|"&E12&"|"&F12 -> 2.8+2512|IR|delta_rw|regular|5y | B12: 2.8+2512 | C12: IR | D12: delta_rw | E12: regular | F12: 5y | G12: 61 | H12: multiplier of per-1bp sensitivity | I12: ISDA SIMM Methodology v2.8+2512 (based on v2.8+2512.2, 13 May 2026) | J12: 2.8+2512 | K12: 2026-07-11 | L12: D.1 | M12: 33 | N12: Table 1 risk weights per vertex | O12: 14 | P12: https://www.isda.org/a/hhkiE/ISDA-SIMM_v2.82512_PUBLIC.pdf | Q12: 2026-10-02 | R12: 8484d3de7dcb5280b6ad6458d051c50f8ccc3370bc279ae1c47a7bccb8064636 | S12: VERIFIED_PRIMARY | T12: two extractors agree (PyMuPDF, markitdown; sequence) + page image check
A13: =B13&"|"&C13&"|"&D13&"|"&E13&"|"&F13 -> 2.8+2512|IR|delta_rw|regular|10y | B13: 2.8+2512 | C13: IR | D13: delta_rw | E13: regular | F13: 10y | G13: 60 | H13: multiplier of per-1bp sensitivity | I13: ISDA SIMM Methodology v2.8+2512 (based on v2.8+2512.2, 13 May 2026) | J13: 2.8+2512 | K13: 2026-07-11 | L13: D.1 | M13: 33 | N13: Table 1 risk weights per vertex | O13: 14 | P13: https://www.isda.org/a/hhkiE/ISDA-SIMM_v2.82512_PUBLIC.pdf | Q13: 2026-10-02 | R13: 8484d3de7dcb5280b6ad6458d051c50f8ccc3370bc279ae1c47a7bccb8064636 | S13: VERIFIED_PRIMARY | T13: two extractors agree (PyMuPDF, markitdown; sequence) + page image check
A14: =B14&"|"&C14&"|"&D14&"|"&E14&"|"&F14 -> 2.8+2512|IR|delta_rw|regular|15y | B14: 2.8+2512 | C14: IR | D14: delta_rw | E14: regular | F14: 15y | G14: 58 | H14: multiplier of per-1bp sensitivity | I14: ISDA SIMM Methodology v2.8+2512 (based on v2.8+2512.2, 13 May 2026) | J14: 2.8+2512 | K14: 2026-07-11 | L14: D.1 | M14: 33 | N14: Table 1 risk weights per vertex | O14: 14 | P14: https://www.isda.org/a/hhkiE/ISDA-SIMM_v2.82512_PUBLIC.pdf | Q14: 2026-10-02 | R14: 8484d3de7dcb5280b6ad6458d051c50f8ccc3370bc279ae1c47a7bccb8064636 | S14: VERIFIED_PRIMARY | T14: two extractors agree (PyMuPDF, markitdown; sequence) + page image check
A15: =B15&"|"&C15&"|"&D15&"|"&E15&"|"&F15 -> 2.8+2512|IR|delta_rw|regular|20y | B15: 2.8+2512 | C15: IR | D15: delta_rw | E15: regular | F15: 20y | G15: 58 | H15: multiplier of per-1bp sensitivity | I15: ISDA SIMM Methodology v2.8+2512 (based on v2.8+2512.2, 13 May 2026) | J15: 2.8+2512 | K15: 2026-07-11 | L15: D.1 | M15: 33 | N15: Table 1 risk weights per vertex | O15: 14 | P15: https://www.isda.org/a/hhkiE/ISDA-SIMM_v2.82512_PUBLIC.pdf | Q15: 2026-10-02 | R15: 8484d3de7dcb5280b6ad6458d051c50f8ccc3370bc279ae1c47a7bccb8064636 | S15: VERIFIED_PRIMARY | T15: two extractors agree (PyMuPDF, markitdown; sequence) + page image check
A16: =B16&"|"&C16&"|"&D16&"|"&E16&"|"&F16 -> 2.8+2512|IR|delta_rw|regular|30y | B16: 2.8+2512 | C16: IR | D16: delta_rw | E16: regular | F16: 30y | G16: 66 | H16: multiplier of per-1bp sensitivity | I16: ISDA SIMM Methodology v2.8+2512 (based on v2.8+2512.2, 13 May 2026) | J16: 2.8+2512 | K16: 2026-07-11 | L16: D.1 | M16: 33 | N16: Table 1 risk weights per vertex | O16: 14 | P16: https://www.isda.org/a/hhkiE/ISDA-SIMM_v2.82512_PUBLIC.pdf | Q16: 2026-10-02 | R16: 8484d3de7dcb5280b6ad6458d051c50f8ccc3370bc279ae1c47a7bccb8064636 | S16: VERIFIED_PRIMARY | T16: two extractors agree (PyMuPDF, markitdown; sequence) + page image check
... A40: =B40&"|"&C40&"|"&D40&"|"&E40&"|"&F40 -> 2.8+2512|IR|delta_rw|high|30y | B40: 2.8+2512 | C40: IR | D40: delta_rw | E40: high | F40: 30y | G40: 96 | H40: multiplier of per-1bp sensitivity | I40: ISDA SIMM Methodology v2.8+2512 (based on v2.8+2512.2, 13 May 2026) | J40: 2.8+2512 | K40: 2026-07-11 | L40: D.1 | M40: 33 | N40: Table 3 risk weights per vertex | O40: 14 | P40: https://www.isda.org/a/hhkiE/ISDA-SIMM_v2.82512_PUBLIC.pdf | Q40: 2026-10-02 | R40: 8484d3de7dcb5280b6ad6458d051c50f8ccc3370bc279ae1c47a7bccb8064636 | S40: VERIFIED_PRIMARY | T40: two extractors agree (PyMuPDF, markitdown; sequence) + page image check
A41: =B41&"|"&C41&"|"&D41&"|"&E41&"|"&F41 -> 2.8+2512|IR|delta_rw_inflation|any| | B41: 2.8+2512 | C41: IR | D41: delta_rw_inflation | E41: any | G41: 51 | H41: multiplier of per-1bp sensitivity | I41: ISDA SIMM Methodology v2.8+2512 (based on v2.8+2512.2, 13 May 2026) | J41: 2.8+2512 | K41: 2026-07-11 | L41: D.1 | M41: 33 | N41: text below Table 3 | O41: 14 | P41: https://www.isda.org/a/hhkiE/ISDA-SIMM_v2.82512_PUBLIC.pdf | Q41: 2026-10-02 | R41: 8484d3de7dcb5280b6ad6458d051c50f8ccc3370bc279ae1c47a7bccb8064636 | S41: VERIFIED_PRIMARY | T41: two extractors agree (PyMuPDF, markitdown; sequence) + page image check
A42: =B42&"|"&C42&"|"&D42&"|"&E42&"|"&F42 -> 2.8+2512|IR|delta_rw_xccy_basis|any| | B42: 2.8+2512 | C42: IR | D42: delta_rw_xccy_basis | E42: any | G42: 21 | H42: multiplier of per-1bp sensitivity | I42: ISDA SIMM Methodology v2.8+2512 (based on v2.8+2512.2, 13 May 2026) | J42: 2.8+2512 | K42: 2026-07-11 | L42: D.1 | M42: 33 | N42: text below Table 3 | O42: 14 | P42: https://www.isda.org/a/hhkiE/ISDA-SIMM_v2.82512_PUBLIC.pdf | Q42: 2026-10-02 | R42: 8484d3de7dcb5280b6ad6458d051c50f8ccc3370bc279ae1c47a7bccb8064636 | S42: VERIFIED_PRIMARY | T42: two extractors agree (PyMuPDF, markitdown; sequence) + page image check
A43: =B43&"|"&C43&"|"&D43&"|"&E43&"|"&F43 -> 2.8+2512|IR|hvr|| | B43: 2.8+2512 | C43: IR | D43: hvr | G43: 0.74 | H43: ratio | I43: ISDA SIMM Methodology v2.8+2512 (based on v2.8+2512.2, 13 May 2026) | J43: 2.8+2512 | K43: 2026-07-11 | L43: D.1 | M43: 34 | N43: text of paragraph 34 (no table) | O43: 14 | P43: https://www.isda.org/a/hhkiE/ISDA-SIMM_v2.82512_PUBLIC.pdf | Q43: 2026-10-02 | R43: 8484d3de7dcb5280b6ad6458d051c50f8ccc3370bc279ae1c47a7bccb8064636 | S43: VERIFIED_PRIMARY | T43: two extractors agree (PyMuPDF, markitdown; sequence) + page image check
A44: =B44&"|"&C44&"|"&D44&"|"&E44&"|"&F44 -> 2.8+2512|IR|vega_rw|| | B44: 2.8+2512 | C44: IR | D44: vega_rw | G44: 0.2 | H44: ratio | I44: ISDA SIMM Methodology v2.8+2512 (based on v2.8+2512.2, 13 May 2026) | J44: 2.8+2512 | K44: 2026-07-11 | L44: D.1 | M44: 35 | N44: text of paragraph 35 (no table) | O44: 14 | P44: https://www.isda.org/a/hhkiE/ISDA-SIMM_v2.82512_PUBLIC.pdf | Q44: 2026-10-02 | R44: 8484d3de7dcb5280b6ad6458d051c50f8ccc3370bc279ae1c47a7bccb8064636 | S44: VERIFIED_PRIMARY | T44: two extractors agree (PyMuPDF, markitdown; sequence) + page image check
A45: =B45&"|"&C45&"|"&D45&"|"&E45&"|"&F45 -> 2.8+2512|IR|rw_group_member|regular|USD | B45: 2.8+2512 | C45: IR | D45: rw_group_member | E45: regular | F45: USD | G45: 1 | H45: membership | I45: ISDA SIMM Methodology v2.8+2512 (based on v2.8+2512.2, 13 May 2026) | J45: 2.8+2512 | K45: 2026-07-11 | L45: D.1 | M45: 33(1) | N45: text of paragraph 33(1) (no table) | O45: 14 | P45: https://www.isda.org/a/hhkiE/ISDA-SIMM_v2.82512_PUBLIC.pdf | Q45: 2026-10-02 | R45: 8484d3de7dcb5280b6ad6458d051c50f8ccc3370bc279ae1c47a7bccb8064636 | S45: VERIFIED_PRIMARY | T45: two extractors agree (PyMuPDF, markitdown; sequence) + page image check
A46: =B46&"|"&C46&"|"&D46&"|"&E46&"|"&F46 -> 2.8+2512|IR|rw_group_member|regular|EUR | B46: 2.8+2512 | C46: IR | D46: rw_group_member | E46: regular | F46: EUR | G46: 1 | H46: membership | I46: ISDA SIMM Methodology v2.8+2512 (based on v2.8+2512.2, 13 May 2026) | J46: 2.8+2512 | K46: 2026-07-11 | L46: D.1 | M46: 33(1) | N46: text of paragraph 33(1) (no table) | O46: 14 | P46: https://www.isda.org/a/hhkiE/ISDA-SIMM_v2.82512_PUBLIC.pdf | Q46: 2026-10-02 | R46: 8484d3de7dcb5280b6ad6458d051c50f8ccc3370bc279ae1c47a7bccb8064636 | S46: VERIFIED_PRIMARY | T46: two extractors agree (PyMuPDF, markitdown; sequence) + page image check
A47: =B47&"|"&C47&"|"&D47&"|"&E47&"|"&F47 -> 2.8+2512|IR|rw_group_member|regular|GBP | B47: 2.8+2512 | C47: IR | D47: rw_group_member | E47: regular | F47: GBP | G47: 1 | H47: membership | I47: ISDA SIMM Methodology v2.8+2512 (based on v2.8+2512.2, 13 May 2026) | J47: 2.8+2512 | K47: 2026-07-11 | L47: D.1 | M47: 33(1) | N47: text of paragraph 33(1) (no table) | O47: 14 | P47: https://www.isda.org/a/hhkiE/ISDA-SIMM_v2.82512_PUBLIC.pdf | Q47: 2026-10-02 | R47: 8484d3de7dcb5280b6ad6458d051c50f8ccc3370bc279ae1c47a7bccb8064636 | S47: VERIFIED_PRIMARY | T47: two extractors agree (PyMuPDF, markitdown; sequence) + page image check
A48: =B48&"|"&C48&"|"&D48&"|"&E48&"|"&F48 -> 2.8+2512|IR|rw_group_member|regular|CHF | B48: 2.8+2512 | C48: IR | D48: rw_group_member | E48: regular | F48: CHF | G48: 1 | H48: membership | I48: ISDA SIMM Methodology v2.8+2512 (based on v2.8+2512.2, 13 May 2026) | J48: 2.8+2512 | K48: 2026-07-11 | L48: D.1 | M48: 33(1) | N48: text of paragraph 33(1) (no table) | O48: 14 | P48: https://www.isda.org/a/hhkiE/ISDA-SIMM_v2.82512_PUBLIC.pdf | Q48: 2026-10-02 | R48: 8484d3de7dcb5280b6ad6458d051c50f8ccc3370bc279ae1c47a7bccb8064636 | S48: VERIFIED_PRIMARY | T48: two extractors agree (PyMuPDF, markitdown; sequence) + page image check
A49: =B49&"|"&C49&"|"&D49&"|"&E49&"|"&F49 -> 2.8+2512|IR|rw_group_member|regular|AUD | B49: 2.8+2512 | C49: IR | D49: rw_group_member | E49: regular | F49: AUD | G49: 1 | H49: membership | I49: ISDA SIMM Methodology v2.8+2512 (based on v2.8+2512.2, 13 May 2026) | J49: 2.8+2512 | K49: 2026-07-11 | L49: D.1 | M49: 33(1) | N49: text of paragraph 33(1) (no table) | O49: 14 | P49: https://www.isda.org/a/hhkiE/ISDA-SIMM_v2.82512_PUBLIC.pdf | Q49: 2026-10-02 | R49: 8484d3de7dcb5280b6ad6458d051c50f8ccc3370bc279ae1c47a7bccb8064636 | S49: VERIFIED_PRIMARY | T49: two extractors agree (PyMuPDF, markitdown; sequence) + page image check
A50: =B50&"|"&C50&"|"&D50&"|"&E50&"|"&F50 -> 2.8+2512|IR|rw_group_member|regular|NZD | B50: 2.8+2512 | C50: IR | D50: rw_group_member | E50: regular | F50: NZD | G50: 1 | H50: membership | I50: ISDA SIMM Methodology v2.8+2512 (based on v2.8+2512.2, 13 May 2026) | J50: 2.8+2512 | K50: 2026-07-11 | L50: D.1 | M50: 33(1) | N50: text of paragraph 33(1) (no table) | O50: 14 | P50: https://www.isda.org/a/hhkiE/ISDA-SIMM_v2.82512_PUBLIC.pdf | Q50: 2026-10-02 | R50: 8484d3de7dcb5280b6ad6458d051c50f8ccc3370bc279ae1c47a7bccb8064636 | S50: VERIFIED_PRIMARY | T50: two extractors agree (PyMuPDF, markitdown; sequence) + page image check
A51: =B51&"|"&C51&"|"&D51&"|"&E51&"|"&F51 -> 2.8+2512|IR|rw_group_member|regular|CAD | B51: 2.8+2512 | C51: IR | D51: rw_group_member | E51: regular | F51: CAD | G51: 1 | H51: membership | I51: ISDA SIMM Methodology v2.8+2512 (based on v2.8+2512.2, 13 May 2026) | J51: 2.8+2512 | K51: 2026-07-11 | L51: D.1 | M51: 33(1) | N51: text of paragraph 33(1) (no table) | O51: 14 | P51: https://www.isda.org/a/hhkiE/ISDA-SIMM_v2.82512_PUBLIC.pdf | Q51: 2026-10-02 | R51: 8484d3de7dcb5280b6ad6458d051c50f8ccc3370bc279ae1c47a7bccb8064636 | S51: VERIFIED_PRIMARY | T51: two extractors agree (PyMuPDF, markitdown; sequence) + page image check
A52: =B52&"|"&C52&"|"&D52&"|"&E52&"|"&F52 -> 2.8+2512|IR|rw_group_member|regular|SEK | B52: 2.8+2512 | C52: IR | D52: rw_group_member | E52: regular | F52: SEK | G52: 1 | H52: membership | I52: ISDA SIMM Methodology v2.8+2512 (based on v2.8+2512.2, 13 May 2026) | J52: 2.8+2512 | K52: 2026-07-11 | L52: D.1 | M52: 33(1) | N52: text of paragraph 33(1) (no table) | O52: 14 | P52: https://www.isda.org/a/hhkiE/ISDA-SIMM_v2.82512_PUBLIC.pdf | Q52: 2026-10-02 | R52: 8484d3de7dcb5280b6ad6458d051c50f8ccc3370bc279ae1c47a7bccb8064636 | S52: VERIFIED_PRIMARY | T52: two extractors agree (PyMuPDF, markitdown; sequence) + page image check
A53: =B53&"|"&C53&"|"&D53&"|"&E53&"|"&F53 -> 2.8+2512|IR|rw_group_member|regular|NOK | B53: 2.8+2512 | C53: IR | D53: rw_group_member | E53: regular | F53: NOK | G53: 1 | H53: membership | I53: ISDA SIMM Methodology v2.8+2512 (based on v2.8+2512.2, 13 May 2026) | J53: 2.8+2512 | K53: 2026-07-11 | L53: D.1 | M53: 33(1) | N53: text of paragraph 33(1) (no table) | O53: 14 | P53: https://www.isda.org/a/hhkiE/ISDA-SIMM_v2.82512_PUBLIC.pdf | Q53: 2026-10-02 | R53: 8484d3de7dcb5280b6ad6458d051c50f8ccc3370bc279ae1c47a7bccb8064636 | S53: VERIFIED_PRIMARY | T53: two extractors agree (PyMuPDF, markitdown; sequence) + page image check
A54: =B54&"|"&C54&"|"&D54&"|"&E54&"|"&F54 -> 2.8+2512|IR|rw_group_member|regular|DKK | B54: 2.8+2512 | C54: IR | D54: rw_group_member | E54: regular | F54: DKK | G54: 1 | H54: membership | I54: ISDA SIMM Methodology v2.8+2512 (based on v2.8+2512.2, 13 May 2026) | J54: 2.8+2512 | K54: 2026-07-11 | L54: D.1 | M54: 33(1) | N54: text of paragraph 33(1) (no table) | O54: 14 | P54: https://www.isda.org/a/hhkiE/ISDA-SIMM_v2.82512_PUBLIC.pdf | Q54: 2026-10-02 | R54: 8484d3de7dcb5280b6ad6458d051c50f8ccc3370bc279ae1c47a7bccb8064636 | S54: VERIFIED_PRIMARY | T54: two extractors agree (PyMuPDF, markitdown; sequence) + page image check
A55: =B55&"|"&C55&"|"&D55&"|"&E55&"|"&F55 -> 2.8+2512|IR|rw_group_member|regular|HKD | B55: 2.8+2512 | C55: IR | D55: rw_group_member | E55: regular | F55: HKD | G55: 1 | H55: membership | I55: ISDA SIMM Methodology v2.8+2512 (based on v2.8+2512.2, 13 May 2026) | J55: 2.8+2512 | K55: 2026-07-11 | L55: D.1 | M55: 33(1) | N55: text of paragraph 33(1) (no table) | O55: 14 | P55: https://www.isda.org/a/hhkiE/ISDA-SIMM_v2.82512_PUBLIC.pdf | Q55: 2026-10-02 | R55: 8484d3de7dcb5280b6ad6458d051c50f8ccc3370bc279ae1c47a7bccb8064636 | S55: VERIFIED_PRIMARY | T55: two extractors agree (PyMuPDF, markitdown; sequence) + page image check
A56: =B56&"|"&C56&"|"&D56&"|"&E56&"|"&F56 -> 2.8+2512|IR|rw_group_member|regular|KRW | B56: 2.8+2512 | C56: IR | D56: rw_group_member | E56: regular | F56: KRW | G56: 1 | H56: membership | I56: ISDA SIMM Methodology v2.8+2512 (based on v2.8+2512.2, 13 May 2026) | J56: 2.8+2512 | K56: 2026-07-11 | L56: D.1 | M56: 33(1) | N56: text of paragraph 33(1) (no table) | O56: 14 | P56: https://www.isda.org/a/hhkiE/ISDA-SIMM_v2.82512_PUBLIC.pdf | Q56: 2026-10-02 | R56: 8484d3de7dcb5280b6ad6458d051c50f8ccc3370bc279ae1c47a7bccb8064636 | S56: VERIFIED_PRIMARY | T56: two extractors agree (PyMuPDF, markitdown; sequence) + page image check
... A204: =B204&"|"&C204&"|"&D204&"|"&E204&"|"&F204 -> 2.8+2512|IR|delta_tenor_corr|30y|30y | B204: 2.8+2512 | C204: IR | D204: delta_tenor_corr | E204: 30y | F204: 30y | G204: 1 | H204: fraction | I204: ISDA SIMM Methodology v2.8+2512 (based on v2.8+2512.2, 13 May 2026) | J204: 2.8+2512 | K204: 2026-07-11 | L204: D.2 | M204: 36 | N204: correlation matrix for aggregated weighted sensitivities or risk exposures (row 30y) | O204: 15 | P204: https://www.isda.org/a/hhkiE/ISDA-SIMM_v2.82512_PUBLIC.pdf | Q204: 2026-10-02 | R204: 8484d3de7dcb5280b6ad6458d051c50f8ccc3370bc279ae1c47a7bccb8064636 | S204: VERIFIED_PRIMARY | T204: two extractors agree (PyMuPDF, markitdown; sequence) + page image check; diagonal blank in source, 1 by definition
A205: =B205&"|"&C205&"|"&D205&"|"&E205&"|"&F205 -> 2.8+2512|IR|subcurve_phi|| | B205: 2.8+2512 | C205: IR | D205: subcurve_phi | G205: 0.981 | H205: fraction | I205: ISDA SIMM Methodology v2.8+2512 (based on v2.8+2512.2, 13 May 2026) | J205: 2.8+2512 | K205: 2026-07-11 | L205: D.2 | M205: 36 | N205: text under matrix (to one decimal place) | O205: 15 | P205: https://www.isda.org/a/hhkiE/ISDA-SIMM_v2.82512_PUBLIC.pdf | Q205: 2026-10-02 | R205: 8484d3de7dcb5280b6ad6458d051c50f8ccc3370bc279ae1c47a7bccb8064636 | S205: VERIFIED_PRIMARY | T205: two extractors agree (PyMuPDF, markitdown; sequence) + page image check
A206: =B206&"|"&C206&"|"&D206&"|"&E206&"|"&F206 -> 2.8+2512|IR|inflation_yield_corr|| | B206: 2.8+2512 | C206: IR | D206: inflation_yield_corr | G206: 0.42 | H206: fraction | I206: ISDA SIMM Methodology v2.8+2512 (based on v2.8+2512.2, 13 May 2026) | J206: 2.8+2512 | K206: 2026-07-11 | L206: D.2 | M206: 36 | N206: text under matrix | O206: 15 | P206: https://www.isda.org/a/hhkiE/ISDA-SIMM_v2.82512_PUBLIC.pdf | Q206: 2026-10-02 | R206: 8484d3de7dcb5280b6ad6458d051c50f8ccc3370bc279ae1c47a7bccb8064636 | S206: VERIFIED_PRIMARY | T206: two extractors agree (PyMuPDF, markitdown; sequence) + page image check
A207: =B207&"|"&C207&"|"&D207&"|"&E207&"|"&F207 -> 2.8+2512|IR|inflation_vol_ir_vol_corr|| | B207: 2.8+2512 | C207: IR | D207: inflation_vol_ir_vol_corr | G207: 0.42 | H207: fraction | I207: ISDA SIMM Methodology v2.8+2512 (based on v2.8+2512.2, 13 May 2026) | J207: 2.8+2512 | K207: 2026-07-11 | L207: D.2 | M207: 36 | N207: same sentence: inflation vol vs IR vol | O207: 15 | P207: https://www.isda.org/a/hhkiE/ISDA-SIMM_v2.82512_PUBLIC.pdf | Q207: 2026-10-02 | R207: 8484d3de7dcb5280b6ad6458d051c50f8ccc3370bc279ae1c47a7bccb8064636 | S207: VERIFIED_PRIMARY | T207: two extractors agree (PyMuPDF, markitdown; sequence) + page image check
A208: =B208&"|"&C208&"|"&D208&"|"&E208&"|"&F208 -> 2.8+2512|IR|xccy_basis_yield_corr|| | B208: 2.8+2512 | C208: IR | D208: xccy_basis_yield_corr | G208: -0.01 | H208: fraction | I208: ISDA SIMM Methodology v2.8+2512 (based on v2.8+2512.2, 13 May 2026) | J208: 2.8+2512 | K208: 2026-07-11 | L208: D.2 | M208: 36 | N208: text under matrix (vs yield or inflation, same currency) | O208: 15 | P208: https://www.isda.org/a/hhkiE/ISDA-SIMM_v2.82512_PUBLIC.pdf | Q208: 2026-10-02 | R208: 8484d3de7dcb5280b6ad6458d051c50f8ccc3370bc279ae1c47a7bccb8064636 | S208: VERIFIED_PRIMARY | T208: two extractors agree (PyMuPDF, markitdown; sequence) + page image check
A209: =B209&"|"&C209&"|"&D209&"|"&E209&"|"&F209 -> 2.8+2512|IR|gamma|| | B209: 2.8+2512 | C209: IR | D209: gamma | G209: 0.35 | H209: fraction | I209: ISDA SIMM Methodology v2.8+2512 (based on v2.8+2512.2, 13 May 2026) | J209: 2.8+2512 | K209: 2026-07-11 | L209: D.2 | M209: 37 | N209: text of paragraph 37 (no table) | O209: 15 | P209: https://www.isda.org/a/hhkiE/ISDA-SIMM_v2.82512_PUBLIC.pdf | Q209: 2026-10-02 | R209: 8484d3de7dcb5280b6ad6458d051c50f8ccc3370bc279ae1c47a7bccb8064636 | S209: VERIFIED_PRIMARY | T209: two extractors agree (PyMuPDF, markitdown; sequence) + page image check
A210: =B210&"|"&C210&"|"&D210&"|"&E210&"|"&F210 -> 2.8+2512|IR|delta_ct|high| | B210: 2.8+2512 | C210: IR | D210: delta_ct | E210: high | G210: 71 | H210: USD mm per bp | I210: ISDA SIMM Methodology v2.8+2512 (based on v2.8+2512.2, 13 May 2026) | J210: 2.8+2512 | K210: 2026-07-11 | L210: J.1 | M210: 74 | N210: text of paragraph 74 (no table) | O210: 26 | P210: https://www.isda.org/a/hhkiE/ISDA-SIMM_v2.82512_PUBLIC.pdf | Q210: 2026-10-02 | R210: 8484d3de7dcb5280b6ad6458d051c50f8ccc3370bc279ae1c47a7bccb8064636 | S210: VERIFIED_PRIMARY | T210: two extractors agree (PyMuPDF, markitdown; sequence) + page image check
A211: =B211&"|"&C211&"|"&D211&"|"&E211&"|"&F211 -> 2.8+2512|IR|delta_ct|regular_well_traded| | B211: 2.8+2512 | C211: IR | D211: delta_ct | E211: regular_well_traded | G211: 220 | H211: USD mm per bp | I211: ISDA SIMM Methodology v2.8+2512 (based on v2.8+2512.2, 13 May 2026) | J211: 2.8+2512 | K211: 2026-07-11 | L211: J.1 | M211: 74 | N211: text of paragraph 74 (no table) | O211: 26 | P211: https://www.isda.org/a/hhkiE/ISDA-SIMM_v2.82512_PUBLIC.pdf | Q211: 2026-10-02 | R211: 8484d3de7dcb5280b6ad6458d051c50f8ccc3370bc279ae1c47a7bccb8064636 | S211: VERIFIED_PRIMARY | T211: two extractors agree (PyMuPDF, markitdown; sequence) + page image check
A212: =B212&"|"&C212&"|"&D212&"|"&E212&"|"&F212 -> 2.8+2512|IR|delta_ct|regular_less_well_traded| | B212: 2.8+2512 | C212: IR | D212: delta_ct | E212: regular_less_well_traded | G212: 110 | H212: USD mm per bp | I212: ISDA SIMM Methodology v2.8+2512 (based on v2.8+2512.2, 13 May 2026) | J212: 2.8+2512 | K212: 2026-07-11 | L212: J.1 | M212: 74 | N212: text of paragraph 74 (no table) | O212: 26 | P212: https://www.isda.org/a/hhkiE/ISDA-SIMM_v2.82512_PUBLIC.pdf | Q212: 2026-10-02 | R212: 8484d3de7dcb5280b6ad6458d051c50f8ccc3370bc279ae1c47a7bccb8064636 | S212: VERIFIED_PRIMARY | T212: two extractors agree (PyMuPDF, markitdown; sequence) + page image check
...

Sheet Parameters_Reg
A1: Regulatory parameters (typed with provenance): schedule IM rates, weights, BCBS 22 Table 2.
A4: asset_class | B4: maturity_low_years | C4: maturity_high_years (1E9 means open ended) | D4: rate_pct | E4: source_doc | F4: section | G4: verification_status | H4: retrieved_on | J4: constant | K4: value | L4: source_doc | M4: citation | N4: verification_status | P4: exceptions | Q4: zone | R4: plus_factor | S4: source
A5: Credit | B5: 0 | C5: 2 | D5: 2 | E5: 12 CFR Part 45 (OCC), eCFR as of 2026-09-30 | F5: Appendix A to Part 45, Table A (Standardized Minimum Gross Initial Margin Requirements) | G5: VERIFIED_PRIMARY | H5: 2026-10-02 | J5: schedule_gross_weight | K5: 0.4 | L5: 12 CFR Part 45 (OCC), eCFR as of 2026-09-30 | M5: 12 CFR Part 45 Appendix A, footnote 1 | N5: VERIFIED_PRIMARY | P5: 0 | Q5: Green | R5: 0 | S5: BCBS 22 Table 2
A6: Credit | B6: 2 | C6: 5 | D6: 5 | E6: 12 CFR Part 45 (OCC), eCFR as of 2026-09-30 | F6: Appendix A to Part 45, Table A (Standardized Minimum Gross Initial Margin Requirements) | G6: VERIFIED_PRIMARY | H6: 2026-10-02 | J6: schedule_ngr_weight | K6: 0.6 | L6: 12 CFR Part 45 (OCC), eCFR as of 2026-09-30 | M6: 12 CFR Part 45 Appendix A, footnote 1 | N6: VERIFIED_PRIMARY | P6: 1 | Q6: Green | R6: 0 | S6: BCBS 22 Table 2
A7: Credit | B7: 5 | C7: 1000000000 | D7: 10 | E7: 12 CFR Part 45 (OCC), eCFR as of 2026-09-30 | F7: Appendix A to Part 45, Table A (Standardized Minimum Gross Initial Margin Requirements) | G7: VERIFIED_PRIMARY | H7: 2026-10-02 | P7: 2 | Q7: Green | R7: 0 | S7: BCBS 22 Table 2
A8: Commodity | B8: 0 | C8: 1000000000 | D8: 15 | E8: 12 CFR Part 45 (OCC), eCFR as of 2026-09-30 | F8: Appendix A to Part 45, Table A (Standardized Minimum Gross Initial Margin Requirements) | G8: VERIFIED_PRIMARY | H8: 2026-10-02 | P8: 3 | Q8: Green | R8: 0 | S8: BCBS 22 Table 2
A9: Equity | B9: 0 | C9: 1000000000 | D9: 15 | E9: 12 CFR Part 45 (OCC), eCFR as of 2026-09-30 | F9: Appendix A to Part 45, Table A (Standardized Minimum Gross Initial Margin Requirements) | G9: VERIFIED_PRIMARY | H9: 2026-10-02 | P9: 4 | Q9: Green | R9: 0 | S9: BCBS 22 Table 2
A10: Foreign exchange | B10: 0 | C10: 1000000000 | D10: 6 | E10: 12 CFR Part 45 (OCC), eCFR as of 2026-09-30 | F10: Appendix A to Part 45, Table A (Standardized Minimum Gross Initial Margin Requirements) | G10: VERIFIED_PRIMARY | H10: 2026-10-02 | P10: 5 | Q10: Yellow | R10: 0.4 | S10: BCBS 22 Table 2
A11: Cross-currency swap | B11: 0 | C11: 2 | D11: 1 | E11: 12 CFR Part 45 (OCC), eCFR as of 2026-09-30 | F11: Appendix A to Part 45, Table A (Standardized Minimum Gross Initial Margin Requirements) | G11: VERIFIED_PRIMARY | H11: 2026-10-02 | P11: 6 | Q11: Yellow | R11: 0.5 | S11: BCBS 22 Table 2
A12: Cross-currency swap | B12: 2 | C12: 5 | D12: 2 | E12: 12 CFR Part 45 (OCC), eCFR as of 2026-09-30 | F12: Appendix A to Part 45, Table A (Standardized Minimum Gross Initial Margin Requirements) | G12: VERIFIED_PRIMARY | H12: 2026-10-02 | P12: 7 | Q12: Yellow | R12: 0.65 | S12: BCBS 22 Table 2
A13: Cross-currency swap | B13: 5 | C13: 1000000000 | D13: 4 | E13: 12 CFR Part 45 (OCC), eCFR as of 2026-09-30 | F13: Appendix A to Part 45, Table A (Standardized Minimum Gross Initial Margin Requirements) | G13: VERIFIED_PRIMARY | H13: 2026-10-02 | P13: 8 | Q13: Yellow | R13: 0.75 | S13: BCBS 22 Table 2
A14: Interest rate | B14: 0 | C14: 2 | D14: 1 | E14: 12 CFR Part 45 (OCC), eCFR as of 2026-09-30 | F14: Appendix A to Part 45, Table A (Standardized Minimum Gross Initial Margin Requirements) | G14: VERIFIED_PRIMARY | H14: 2026-10-02 | P14: 9 | Q14: Yellow | R14: 0.85 | S14: BCBS 22 Table 2
A15: Interest rate | B15: 2 | C15: 5 | D15: 2 | E15: 12 CFR Part 45 (OCC), eCFR as of 2026-09-30 | F15: Appendix A to Part 45, Table A (Standardized Minimum Gross Initial Margin Requirements) | G15: VERIFIED_PRIMARY | H15: 2026-10-02 | P15: 10 | Q15: Red | R15: 1 | S15: BCBS 22 Table 2
A16: Interest rate | B16: 5 | C16: 1000000000 | D16: 4 | E16: 12 CFR Part 45 (OCC), eCFR as of 2026-09-30 | F16: Appendix A to Part 45, Table A (Standardized Minimum Gross Initial Margin Requirements) | G16: VERIFIED_PRIMARY | H16: 2026-10-02
A17: Other | B17: 0 | C17: 1000000000 | D17: 15 | E17: 12 CFR Part 45 (OCC), eCFR as of 2026-09-30 | F17: Appendix A to Part 45, Table A (Standardized Minimum Gross Initial Margin Requirements) | G17: VERIFIED_PRIMARY | H17: 2026-10-02

Sheet Portfolio
A1: Sample portfolio and PV (typed from Python; SYNTHETIC). PV is in USD.
A4: trade_id | B4: counterparty | C4: product | D4: ccy | E4: ccy2 | F4: notional | G4: direction | H4: start | I4: maturity | J4: expiry | K4: strike | L4: opt_type | M4: pv
A5: IRS_USD_2Y | B5: CPTY_B | C5: IRS | D5: USD | F5: 60000000 | G5: 1 | H5: 0 | I5: 2 | K5: 0.039627916 | M5: 475770.62
A6: IRS_USD_5Y | B6: CPTY_B | C6: IRS | D6: USD | F6: 40000000 | G6: -1 | H6: 0 | I6: 5 | K6: 0.039874146 | M6: -1042407.8
A7: IRS_USD_10Y | B7: CPTY_B | C7: IRS | D7: USD | F7: 25000000 | G7: 1 | H7: 0 | I7: 10 | K7: 0.042921378 | M7: 904650.83
A8: IRS_USD_30Y | B8: CPTY_B | C8: IRS | D8: USD | F8: 10000000 | G8: -1 | H8: 0 | I8: 30 | K8: 0.04576694 | M8: -539620.16
A9: IRS_EUR_5Y | B9: CPTY_B | C9: IRS | D9: EUR | F9: 30000000 | G9: 1 | H9: 0 | I9: 5 | K9: 0.024061862 | M9: 362788
A10: IRS_EUR_10Y | B10: CPTY_B | C10: IRS | D10: EUR | F10: 20000000 | G10: -1 | H10: 0 | I10: 10 | K10: 0.02748556 | M10: 179763.15
A11: IRS_GBP_7Y | B11: CPTY_B | C11: IRS | D11: GBP | F11: 25000000 | G11: 1 | H11: 0 | I11: 7 | K11: 0.041455329 | M11: 152323.83
A12: IRS_JPY_10Y | B12: CPTY_B | C12: IRS | D12: JPY | F12: 4000000000 | G12: -1 | H12: 0 | I12: 10 | K12: 0.013896767 | M12: -865234.25
A13: IRS_MXN_3Y | B13: CPTY_B | C13: IRS | D13: MXN | F13: 500000000 | G13: 1 | H13: 0 | I13: 3 | K13: 0.088246362 | M13: 1891311.2
A14: SWPT_USD_1Yx5Y | B14: CPTY_B | C14: SWAPTION | D14: USD | F14: 50000000 | G14: 1 | H14: 1 | I14: 6 | J14: 1 | K14: 0.042878843 | L14: payer | M14: 1213662.4
A15: SWPT_EUR_4Yx10Y | B15: CPTY_B | C15: SWAPTION | D15: EUR | F15: 30000000 | G15: 1 | H15: 4 | I15: 14 | J15: 4 | K15: 0.02697646 | L15: receiver | M15: 2062559.8
A16: SWPT_GBP_5Yx5Y | B16: CPTY_B | C16: SWAPTION | D16: GBP | F16: 25000000 | G16: -1 | H16: 5 | I16: 10 | J16: 5 | K16: 0.042747772 | L16: payer | M16: -1037840.3
A17: FXF_EURUSD_6M | B17: CPTY_B | C17: FXFWD | D17: EUR | E17: USD | F17: 25000000 | G17: 1 | H17: 0 | I17: 0.5 | K17: 1.0924328 | M17: 3371586.7
A18: FXF_GBPUSD_1Y | B18: CPTY_B | C18: FXFWD | D18: GBP | E18: USD | F18: 15000000 | G18: -1 | H18: 0 | I18: 1 | K18: 1.2629756 | M18: -299975.15
A19: FXF_USDJPY_3M | B19: CPTY_B | C19: FXFWD | D19: USD | E19: JPY | F19: 20000000 | G19: 1 | H19: 0 | I19: 0.25 | K19: 148.35089 | M19: -250225.03
A20: FXF_USDMXN_6M | B20: CPTY_B | C20: FXFWD | D20: USD | E20: MXN | F20: 10000000 | G20: -1 | H20: 0 | I20: 0.5 | K20: 18.635531 | M20: 918421.29
A21: FXO_EURUSD_C3M | B21: CPTY_B | C21: FXOPT | D21: EUR | E21: USD | F21: 20000000 | G21: 1 | H21: 0 | I21: 0.25 | J21: 0.25 | K21: 1.094884 | L21: call | M21: 2572583.6
A22: FXO_USDMXN_C1Y | B22: CPTY_B | C22: FXOPT | D22: USD | E22: MXN | F22: 10000000 | G22: 1 | H22: 0 | I22: 1 | J22: 1 | K22: 19.689494 | L22: call | M22: 187279.15
A23: FXO_GBPUSD_STRADDLE_C | B23: CPTY_B | C23: FXOPT | D23: GBP | E23: USD | F23: 15000000 | G23: 1 | H23: 0 | I23: 0.5 | J23: 0.5 | K23: 1.2704373 | L23: call | M23: 796644.11
A24: FXO_GBPUSD_STRADDLE_P | B24: CPTY_B | C24: FXOPT | D24: GBP | E24: USD | F24: 15000000 | G24: 1 | H24: 0 | I24: 0.5 | J24: 0.5 | K24: 1.2704373 | L24: put | M24: 627283.68

Sheet Sensitivities
A1: CRIF (typed from Python) with live helper columns, and closed-form Bachelier and Garman-Kohlhagen checks (columns O to P).
A4: TradeID | B4: RiskType | C4: Qualifier | D4: Bucket | E4: Label1 | F4: Label2 | G4: Amount | H4: AmountCurrency | I4: AmountUSD | J4: SigmaMarket | K4: fx_vega_per_unit_vol_usd | L4: sf_of_vertex | M4: fx_vega_x_sf | O4: Bachelier swaption (typed inputs, live formulas)
A5: IRS_USD_2Y | B5: Risk_IRCurve | C5: USD | D5: regular_well_traded | E5: 1y | F5: OIS | G5: -22.329121 | H5: USD | I5: -22.329121 | K5: =IF(AND(B5="Risk_FXVol",ISNUMBER(J5)),I5/J5,0) -> 0 | L5: =IF(OR(B5="Risk_FXVol",B5="Risk_IRVol"),INDEX(SIMM_Curvature!$D$15:$D$26,MATCH(E5,SIMM_Curvature!$A$15:$A$26,0)),0) -> 0 | M5: =K5*L5 -> 0 | O5: trade_id | P5: SWPT_USD_1Yx5Y
A6: IRS_USD_2Y | B6: Risk_IRCurve | C6: USD | D6: regular_well_traded | E6: 2y | F6: OIS | G6: 11213.54 | H6: USD | I6: 11213.54 | K6: =IF(AND(B6="Risk_FXVol",ISNUMBER(J6)),I6/J6,0) -> 0 | L6: =IF(OR(B6="Risk_FXVol",B6="Risk_IRVol"),INDEX(SIMM_Curvature!$D$15:$D$26,MATCH(E6,SIMM_Curvature!$A$15:$A$26,0)),0) -> 0 | M6: =K6*L6 -> 0 | O6: notional | P6: 50000000
A7: IRS_USD_5Y | B7: Risk_IRCurve | C7: USD | D7: regular_well_traded | E7: 1y | F7: OIS | G7: 18.262285 | H7: USD | I7: 18.262285 | K7: =IF(AND(B7="Risk_FXVol",ISNUMBER(J7)),I7/J7,0) -> 0 | L7: =IF(OR(B7="Risk_FXVol",B7="Risk_IRVol"),INDEX(SIMM_Curvature!$D$15:$D$26,MATCH(E7,SIMM_Curvature!$A$15:$A$26,0)),0) -> 0 | M7: =K7*L7 -> 0 | O7: direction | P7: 1
A8: IRS_USD_5Y | B8: Risk_IRCurve | C8: USD | D8: regular_well_traded | E8: 2y | F8: OIS | G8: 37.277051 | H8: USD | I8: 37.277051 | K8: =IF(AND(B8="Risk_FXVol",ISNUMBER(J8)),I8/J8,0) -> 0 | L8: =IF(OR(B8="Risk_FXVol",B8="Risk_IRVol"),INDEX(SIMM_Curvature!$D$15:$D$26,MATCH(E8,SIMM_Curvature!$A$15:$A$26,0)),0) -> 0 | M8: =K8*L8 -> 0 | O8: forward swap rate | P8: 0.046903477
A9: IRS_USD_5Y | B9: Risk_IRCurve | C9: USD | D9: regular_well_traded | E9: 3y | F9: OIS | G9: 96.183415 | H9: USD | I9: 96.183415 | K9: =IF(AND(B9="Risk_FXVol",ISNUMBER(J9)),I9/J9,0) -> 0 | L9: =IF(OR(B9="Risk_FXVol",B9="Risk_IRVol"),INDEX(SIMM_Curvature!$D$15:$D$26,MATCH(E9,SIMM_Curvature!$A$15:$A$26,0)),0) -> 0 | M9: =K9*L9 -> 0 | O9: annuity | P9: 4.1934646
A10: IRS_USD_5Y | B10: Risk_IRCurve | C10: USD | D10: regular_well_traded | E10: 5y | F10: OIS | G10: -17421.686 | H10: USD | I10: -17421.686 | K10: =IF(AND(B10="Risk_FXVol",ISNUMBER(J10)),I10/J10,0) -> 0 | L10: =IF(OR(B10="Risk_FXVol",B10="Risk_IRVol"),INDEX(SIMM_Curvature!$D$15:$D$26,MATCH(E10,SIMM_Curvature!$A$15:$A$26,0)),0) -> 0 | M10: =K10*L10 -> 0 | O10: strike | P10: 0.042878843
A11: IRS_USD_10Y | B11: Risk_IRCurve | C11: USD | D11: regular_well_traded | E11: 1y | F11: OIS | G11: -6.9223531 | H11: USD | I11: -6.9223531 | K11: =IF(AND(B11="Risk_FXVol",ISNUMBER(J11)),I11/J11,0) -> 0 | L11: =IF(OR(B11="Risk_FXVol",B11="Risk_IRVol"),INDEX(SIMM_Curvature!$D$15:$D$26,MATCH(E11,SIMM_Curvature!$A$15:$A$26,0)),0) -> 0 | M11: =K11*L11 -> 0 | O11: normal vol (bp) | P11: 85.332318
A12: IRS_USD_10Y | B12: Risk_IRCurve | C12: USD | D12: regular_well_traded | E12: 2y | F12: OIS | G12: -14.129935 | H12: USD | I12: -14.129935 | K12: =IF(AND(B12="Risk_FXVol",ISNUMBER(J12)),I12/J12,0) -> 0 | L12: =IF(OR(B12="Risk_FXVol",B12="Risk_IRVol"),INDEX(SIMM_Curvature!$D$15:$D$26,MATCH(E12,SIMM_Curvature!$A$15:$A$26,0)),0) -> 0 | M12: =K12*L12 -> 0 | O12: expiry (years) | P12: 1
A13: IRS_USD_10Y | B13: Risk_IRCurve | C13: USD | D13: regular_well_traded | E13: 3y | F13: OIS | G13: -36.458501 | H13: USD | I13: -36.458501 | K13: =IF(AND(B13="Risk_FXVol",ISNUMBER(J13)),I13/J13,0) -> 0 | L13: =IF(OR(B13="Risk_FXVol",B13="Risk_IRVol"),INDEX(SIMM_Curvature!$D$15:$D$26,MATCH(E13,SIMM_Curvature!$A$15:$A$26,0)),0) -> 0 | M13: =K13*L13 -> 0 | O13: fx to USD | P13: 1
A14: IRS_USD_10Y | B14: Risk_IRCurve | C14: USD | D14: regular_well_traded | E14: 5y | F14: OIS | G14: -165.78332 | H14: USD | I14: -165.78332 | K14: =IF(AND(B14="Risk_FXVol",ISNUMBER(J14)),I14/J14,0) -> 0 | L14: =IF(OR(B14="Risk_FXVol",B14="Risk_IRVol"),INDEX(SIMM_Curvature!$D$15:$D$26,MATCH(E14,SIMM_Curvature!$A$15:$A$26,0)),0) -> 0 | M14: =K14*L14 -> 0 | O14: normal vol (fraction) | P14: =$P$11/10000 -> 0.0085332318
A15: IRS_USD_10Y | B15: Risk_IRCurve | C15: USD | D15: regular_well_traded | E15: 10y | F15: OIS | G15: 19420.058 | H15: USD | I15: 19420.058 | K15: =IF(AND(B15="Risk_FXVol",ISNUMBER(J15)),I15/J15,0) -> 0 | L15: =IF(OR(B15="Risk_FXVol",B15="Risk_IRVol"),INDEX(SIMM_Curvature!$D$15:$D$26,MATCH(E15,SIMM_Curvature!$A$15:$A$26,0)),0) -> 0 | M15: =K15*L15 -> 0 | O15: vol * sqrt(T) | P15: =$P$14*SQRT($P$12) -> 0.0085332318
A16: IRS_USD_30Y | B16: Risk_IRCurve | C16: USD | D16: regular_well_traded | E16: 1y | F16: OIS | G16: 0.78593511 | H16: USD | I16: 0.78593511 | K16: =IF(AND(B16="Risk_FXVol",ISNUMBER(J16)),I16/J16,0) -> 0 | L16: =IF(OR(B16="Risk_FXVol",B16="Risk_IRVol"),INDEX(SIMM_Curvature!$D$15:$D$26,MATCH(E16,SIMM_Curvature!$A$15:$A$26,0)),0) -> 0 | M16: =K16*L16 -> 0 | O16: d | P16: =($P$8-$P$10)/$P$15 -> 0.47164239
A17: IRS_USD_30Y | B17: Risk_IRCurve | C17: USD | D17: regular_well_traded | E17: 2y | F17: OIS | G17: 1.6042539 | H17: USD | I17: 1.6042539 | K17: =IF(AND(B17="Risk_FXVol",ISNUMBER(J17)),I17/J17,0) -> 0 | L17: =IF(OR(B17="Risk_FXVol",B17="Risk_IRVol"),INDEX(SIMM_Curvature!$D$15:$D$26,MATCH(E17,SIMM_Curvature!$A$15:$A$26,0)),0) -> 0 | M17: =K17*L17 -> 0 | O17: pdf(d) | P17: =EXP(-0.5*$P$16^2)/SQRT(2*PI()) -> 0.3569492
A18: IRS_USD_30Y | B18: Risk_IRCurve | C18: USD | D18: regular_well_traded | E18: 3y | F18: OIS | G18: 4.1393455 | H18: USD | I18: 4.1393455 | K18: =IF(AND(B18="Risk_FXVol",ISNUMBER(J18)),I18/J18,0) -> 0 | L18: =IF(OR(B18="Risk_FXVol",B18="Risk_IRVol"),INDEX(SIMM_Curvature!$D$15:$D$26,MATCH(E18,SIMM_Curvature!$A$15:$A$26,0)),0) -> 0 | M18: =K18*L18 -> 0 | O18: vega per 1bp (USD) | P18: =$P$6*$P$7*$P$9*SQRT($P$12)*$P$17*0.0001*$P$13 -> 7484.2691
A19: IRS_USD_30Y | B19: Risk_IRCurve | C19: USD | D19: regular_well_traded | E19: 5y | F19: OIS | G19: 18.82234 | H19: USD | I19: 18.82234 | K19: =IF(AND(B19="Risk_FXVol",ISNUMBER(J19)),I19/J19,0) -> 0 | L19: =IF(OR(B19="Risk_FXVol",B19="Risk_IRVol"),INDEX(SIMM_Curvature!$D$15:$D$26,MATCH(E19,SIMM_Curvature!$A$15:$A$26,0)),0) -> 0 | M19: =K19*L19 -> 0 | O19: CRIF vega amount, closed form (USD) | P19: =$P$18*$P$11 -> 638650.03
A20: IRS_USD_30Y | B20: Risk_IRCurve | C20: USD | D20: regular_well_traded | E20: 10y | F20: OIS | G20: 49.88731 | H20: USD | I20: 49.88731 | K20: =IF(AND(B20="Risk_FXVol",ISNUMBER(J20)),I20/J20,0) -> 0 | L20: =IF(OR(B20="Risk_FXVol",B20="Risk_IRVol"),INDEX(SIMM_Curvature!$D$15:$D$26,MATCH(E20,SIMM_Curvature!$A$15:$A$26,0)),0) -> 0 | M20: =K20*L20 -> 0 | O20: CRIF vega amount, typed CRIF (USD) | P20: =SUMIFS(Sensitivities!$I$5:$I$100,Sensitivities!$A$5:$A$100,$P$5,Sensitivities!$B$5:$B$100,"Risk_IRVol") -> 638647.77
A21: IRS_USD_30Y | B21: Risk_IRCurve | C21: USD | D21: regular_well_traded | E21: 15y | F21: OIS | G21: 84.79268 | H21: USD | I21: 84.79268 | K21: =IF(AND(B21="Risk_FXVol",ISNUMBER(J21)),I21/J21,0) -> 0 | L21: =IF(OR(B21="Risk_FXVol",B21="Risk_IRVol"),INDEX(SIMM_Curvature!$D$15:$D$26,MATCH(E21,SIMM_Curvature!$A$15:$A$26,0)),0) -> 0 | M21: =K21*L21 -> 0 | O21: PV, closed form payer (USD) | P21: =$P$6*$P$7*$P$9*(($P$8-$P$10)*NORMSDIST($P$16)+$P$15*$P$17)*$P$13 -> 1213662.4
A22: IRS_USD_30Y | B22: Risk_IRCurve | C22: USD | D22: regular_well_traded | E22: 20y | F22: OIS | G22: 221.01489 | H22: USD | I22: 221.01489 | K22: =IF(AND(B22="Risk_FXVol",ISNUMBER(J22)),I22/J22,0) -> 0 | L22: =IF(OR(B22="Risk_FXVol",B22="Risk_IRVol"),INDEX(SIMM_Curvature!$D$15:$D$26,MATCH(E22,SIMM_Curvature!$A$15:$A$26,0)),0) -> 0 | M22: =K22*L22 -> 0 | O22: PV, typed portfolio (USD) | P22: =INDEX(Portfolio!$M$5:$M$24,MATCH($P$5,Portfolio!$A$5:$A$24,0)) -> 1213662.4
A23: IRS_USD_30Y | B23: Risk_IRCurve | C23: USD | D23: regular_well_traded | E23: 30y | F23: OIS | G23: -15368.977 | H23: USD | I23: -15368.977 | K23: =IF(AND(B23="Risk_FXVol",ISNUMBER(J23)),I23/J23,0) -> 0 | L23: =IF(OR(B23="Risk_FXVol",B23="Risk_IRVol"),INDEX(SIMM_Curvature!$D$15:$D$26,MATCH(E23,SIMM_Curvature!$A$15:$A$26,0)),0) -> 0 | M23: =K23*L23 -> 0
A24: IRS_EUR_5Y | B24: Risk_IRCurve | C24: EUR | D24: regular_well_traded | E24: 1y | F24: OIS | G24: -5.5068625 | H24: EUR | I24: -6.715979 | K24: =IF(AND(B24="Risk_FXVol",ISNUMBER(J24)),I24/J24,0) -> 0 | L24: =IF(OR(B24="Risk_FXVol",B24="Risk_IRVol"),INDEX(SIMM_Curvature!$D$15:$D$26,MATCH(E24,SIMM_Curvature!$A$15:$A$26,0)),0) -> 0 | M24: =K24*L24 -> 0
A25: IRS_EUR_5Y | B25: Risk_IRCurve | C25: EUR | D25: regular_well_traded | E25: 2y | F25: OIS | G25: -11.146153 | H25: EUR | I25: -13.593462 | K25: =IF(AND(B25="Risk_FXVol",ISNUMBER(J25)),I25/J25,0) -> 0 | L25: =IF(OR(B25="Risk_FXVol",B25="Risk_IRVol"),INDEX(SIMM_Curvature!$D$15:$D$26,MATCH(E25,SIMM_Curvature!$A$15:$A$26,0)),0) -> 0 | M25: =K25*L25 -> 0
A26: IRS_EUR_5Y | B26: Risk_IRCurve | C26: EUR | D26: regular_well_traded | E26: 3y | F26: OIS | G26: -28.396314 | H26: EUR | I26: -34.631163 | K26: =IF(AND(B26="Risk_FXVol",ISNUMBER(J26)),I26/J26,0) -> 0 | L26: =IF(OR(B26="Risk_FXVol",B26="Risk_IRVol"),INDEX(SIMM_Curvature!$D$15:$D$26,MATCH(E26,SIMM_Curvature!$A$15:$A$26,0)),0) -> 0 | M26: =K26*L26 -> 0 | O26: Garman-Kohlhagen FX call (typed inputs, live formulas)
A27: IRS_EUR_5Y | B27: Risk_IRCurve | C27: EUR | D27: regular_well_traded | E27: 5y | F27: OIS | G27: 13859.96 | H27: EUR | I27: 16903.127 | K27: =IF(AND(B27="Risk_FXVol",ISNUMBER(J27)),I27/J27,0) -> 0 | L27: =IF(OR(B27="Risk_FXVol",B27="Risk_IRVol"),INDEX(SIMM_Curvature!$D$15:$D$26,MATCH(E27,SIMM_Curvature!$A$15:$A$26,0)),0) -> 0 | M27: =K27*L27 -> 0 | O27: trade_id | P27: FXO_GBPUSD_STRADDLE_C
A28: IRS_EUR_5Y | B28: Risk_FX | C28: EUR | G28: 3627.88 | H28: USD | I28: 3627.88 | K28: =IF(AND(B28="Risk_FXVol",ISNUMBER(J28)),I28/J28,0) -> 0 | L28: =IF(OR(B28="Risk_FXVol",B28="Risk_IRVol"),INDEX(SIMM_Curvature!$D$15:$D$26,MATCH(E28,SIMM_Curvature!$A$15:$A$26,0)),0) -> 0 | M28: =K28*L28 -> 0 | O28: notional (base) | P28: 15000000
A29: IRS_EUR_10Y | B29: Risk_IRCurve | C29: EUR | D29: regular_well_traded | E29: 1y | F29: OIS | G29: -1.2634655 | H29: EUR | I29: -1.5408788 | K29: =IF(AND(B29="Risk_FXVol",ISNUMBER(J29)),I29/J29,0) -> 0 | L29: =IF(OR(B29="Risk_FXVol",B29="Risk_IRVol"),INDEX(SIMM_Curvature!$D$15:$D$26,MATCH(E29,SIMM_Curvature!$A$15:$A$26,0)),0) -> 0 | M29: =K29*L29 -> 0 | O29: direction | P29: 1
A30: IRS_EUR_10Y | B30: Risk_IRCurve | C30: EUR | D30: regular_well_traded | E30: 2y | F30: OIS | G30: -2.5573147 | H30: EUR | I30: -3.1188125 | K30: =IF(AND(B30="Risk_FXVol",ISNUMBER(J30)),I30/J30,0) -> 0 | L30: =IF(OR(B30="Risk_FXVol",B30="Risk_IRVol"),INDEX(SIMM_Curvature!$D$15:$D$26,MATCH(E30,SIMM_Curvature!$A$15:$A$26,0)),0) -> 0 | M30: =K30*L30 -> 0 | O30: forward | P30: 1.2819657
A31: IRS_EUR_10Y | B31: Risk_IRCurve | C31: EUR | D31: regular_well_traded | E31: 3y | F31: OIS | G31: -6.5151022 | H31: EUR | I31: -7.9455932 | K31: =IF(AND(B31="Risk_FXVol",ISNUMBER(J31)),I31/J31,0) -> 0 | L31: =IF(OR(B31="Risk_FXVol",B31="Risk_IRVol"),INDEX(SIMM_Curvature!$D$15:$D$26,MATCH(E31,SIMM_Curvature!$A$15:$A$26,0)),0) -> 0 | M31: =K31*L31 -> 0 | O31: strike | P31: 1.2704373
A32: IRS_EUR_10Y | B32: Risk_IRCurve | C32: EUR | D32: regular_well_traded | E32: 5y | F32: OIS | G32: -28.690101 | H32: EUR | I32: -34.989455 | K32: =IF(AND(B32="Risk_FXVol",ISNUMBER(J32)),I32/J32,0) -> 0 | L32: =IF(OR(B32="Risk_FXVol",B32="Risk_IRVol"),INDEX(SIMM_Curvature!$D$15:$D$26,MATCH(E32,SIMM_Curvature!$A$15:$A$26,0)),0) -> 0 | M32: =K32*L32 -> 0 | O32: lognormal vol | P32: 0.13405935
A33: IRS_EUR_10Y | B33: Risk_IRCurve | C33: EUR | D33: regular_well_traded | E33: 10y | F33: OIS | G33: -17420.253 | H33: EUR | I33: -21245.138 | K33: =IF(AND(B33="Risk_FXVol",ISNUMBER(J33)),I33/J33,0) -> 0 | L33: =IF(OR(B33="Risk_FXVol",B33="Risk_IRVol"),INDEX(SIMM_Curvature!$D$15:$D$26,MATCH(E33,SIMM_Curvature!$A$15:$A$26,0)),0) -> 0 | M33: =K33*L33 -> 0 | O33: expiry (years) | P33: 0.5
A34: IRS_EUR_10Y | B34: Risk_FX | C34: EUR | G34: 1797.6315 | H34: USD | I34: 1797.6315 | K34: =IF(AND(B34="Risk_FXVol",ISNUMBER(J34)),I34/J34,0) -> 0 | L34: =IF(OR(B34="Risk_FXVol",B34="Risk_IRVol"),INDEX(SIMM_Curvature!$D$15:$D$26,MATCH(E34,SIMM_Curvature!$A$15:$A$26,0)),0) -> 0 | M34: =K34*L34 -> 0 | O34: discount factor, quote ccy | P34: 0.97938484
A35: IRS_GBP_7Y | B35: Risk_IRCurve | C35: GBP | D35: regular_well_traded | E35: 1y | F35: OIS | G35: -10.719322 | H35: GBP | I35: -13.716418 | K35: =IF(AND(B35="Risk_FXVol",ISNUMBER(J35)),I35/J35,0) -> 0 | L35: =IF(OR(B35="Risk_FXVol",B35="Risk_IRVol"),INDEX(SIMM_Curvature!$D$15:$D$26,MATCH(E35,SIMM_Curvature!$A$15:$A$26,0)),0) -> 0 | M35: =K35*L35 -> 0 | O35: discount factor, base ccy | P35: 0.98119738
A36: IRS_GBP_7Y | B36: Risk_IRCurve | C36: GBP | D36: regular_well_traded | E36: 2y | F36: OIS | G36: -21.837346 | H36: GBP | I36: -27.943014 | K36: =IF(AND(B36="Risk_FXVol",ISNUMBER(J36)),I36/J36,0) -> 0 | L36: =IF(OR(B36="Risk_FXVol",B36="Risk_IRVol"),INDEX(SIMM_Curvature!$D$15:$D$26,MATCH(E36,SIMM_Curvature!$A$15:$A$26,0)),0) -> 0 | M36: =K36*L36 -> 0 | O36: spot of base in USD | P36: 1.2795975
A37: IRS_GBP_7Y | B37: Risk_IRCurve | C37: GBP | D37: regular_well_traded | E37: 3y | F37: OIS | G37: -56.235414 | H37: GBP | I37: -71.958697 | K37: =IF(AND(B37="Risk_FXVol",ISNUMBER(J37)),I37/J37,0) -> 0 | L37: =IF(OR(B37="Risk_FXVol",B37="Risk_IRVol"),INDEX(SIMM_Curvature!$D$15:$D$26,MATCH(E37,SIMM_Curvature!$A$15:$A$26,0)),0) -> 0 | M37: =K37*L37 -> 0 | O37: quote ccy to USD | P37: 1
A38: IRS_GBP_7Y | B38: Risk_IRCurve | C38: GBP | D38: regular_well_traded | E38: 5y | F38: OIS | G38: 8895.5289 | H38: GBP | I38: 11382.697 | K38: =IF(AND(B38="Risk_FXVol",ISNUMBER(J38)),I38/J38,0) -> 0 | L38: =IF(OR(B38="Risk_FXVol",B38="Risk_IRVol"),INDEX(SIMM_Curvature!$D$15:$D$26,MATCH(E38,SIMM_Curvature!$A$15:$A$26,0)),0) -> 0 | M38: =K38*L38 -> 0 | O38: vol * sqrt(T) | P38: =$P$32*SQRT($P$33) -> 0.094794273
A39: IRS_GBP_7Y | B39: Risk_IRCurve | C39: GBP | D39: regular_well_traded | E39: 10y | F39: OIS | G39: 6054.1928 | H39: GBP | I39: 7746.9301 | K39: =IF(AND(B39="Risk_FXVol",ISNUMBER(J39)),I39/J39,0) -> 0 | L39: =IF(OR(B39="Risk_FXVol",B39="Risk_IRVol"),INDEX(SIMM_Curvature!$D$15:$D$26,MATCH(E39,SIMM_Curvature!$A$15:$A$26,0)),0) -> 0 | M39: =K39*L39 -> 0 | O39: d1 | P39: =(LN($P$30/$P$31)+0.5*$P$38^2)/$P$38 -> 0.14269187
A40: IRS_GBP_7Y | B40: Risk_FX | C40: GBP | G40: 1523.2383 | H40: USD | I40: 1523.2383 | K40: =IF(AND(B40="Risk_FXVol",ISNUMBER(J40)),I40/J40,0) -> 0 | L40: =IF(OR(B40="Risk_FXVol",B40="Risk_IRVol"),INDEX(SIMM_Curvature!$D$15:$D$26,MATCH(E40,SIMM_Curvature!$A$15:$A$26,0)),0) -> 0 | M40: =K40*L40 -> 0 | O40: d2 | P40: =$P$39-$P$38 -> 0.0478976
A41: IRS_JPY_10Y | B41: Risk_IRCurve | C41: JPY | D41: regular_low_vol | E41: 1y | F41: OIS | G41: 1186.7528 | H41: JPY | I41: 8.0344351 | K41: =IF(AND(B41="Risk_FXVol",ISNUMBER(J41)),I41/J41,0) -> 0 | L41: =IF(OR(B41="Risk_FXVol",B41="Risk_IRVol"),INDEX(SIMM_Curvature!$D$15:$D$26,MATCH(E41,SIMM_Curvature!$A$15:$A$26,0)),0) -> 0 | M41: =K41*L41 -> 0 | O41: PV, closed form (USD) | P41: =$P$28*$P$29*$P$34*($P$30*NORMSDIST($P$39)-$P$31*NORMSDIST($P$40))*$P$37 -> 796644.11
A42: IRS_JPY_10Y | B42: Risk_IRCurve | C42: JPY | D42: regular_low_vol | E42: 2y | F42: OIS | G42: 2381.7844 | H42: JPY | I42: 16.124919 | K42: =IF(AND(B42="Risk_FXVol",ISNUMBER(J42)),I42/J42,0) -> 0 | L42: =IF(OR(B42="Risk_FXVol",B42="Risk_IRVol"),INDEX(SIMM_Curvature!$D$15:$D$26,MATCH(E42,SIMM_Curvature!$A$15:$A$26,0)),0) -> 0 | M42: =K42*L42 -> 0 | O42: CRIF vega amount, closed form (USD) | P42: =$P$28*$P$29*$P$34*$P$30*EXP(-0.5*$P$39^2)/SQRT(2*PI())*SQRT($P$33)*$P$32*$P$37 -> 705004.47
...

Sheet SIMM_Delta
A1: IR and FX delta. All numbers are formulas: risk weights and thresholds by lookup on Parameters, CR, WS, K, S, aggregation.
A4: Parameter set | B4: =Inputs!$B$4 -> 2.8+2512
A6: IR tenor correlation (12x12)
B7: =Inputs!$B$14 -> 2w | C7: =Inputs!$C$14 -> 1m | D7: =Inputs!$D$14 -> 3m | E7: =Inputs!$E$14 -> 6m | F7: =Inputs!$F$14 -> 1y | G7: =Inputs!$G$14 -> 2y | H7: =Inputs!$H$14 -> 3y | I7: =Inputs!$I$14 -> 5y | J7: =Inputs!$J$14 -> 10y | K7: =Inputs!$K$14 -> 15y | L7: =Inputs!$L$14 -> 20y | M7: =Inputs!$M$14 -> 30y
A8: =Inputs!$B$14 -> 2w | B8: =INDEX(Parameters!$G$5:$G$689,MATCH(Inputs!$B$4&"|IR|"&"delta_tenor_corr"&"|"&$A8&"|"&B$7,Parameters!$A$5:$A$689,0)) -> 1 | C8: =INDEX(Parameters!$G$5:$G$689,MATCH(Inputs!$B$4&"|IR|"&"delta_tenor_corr"&"|"&$A8&"|"&C$7,Parameters!$A$5:$A$689,0)) -> 0.74 | D8: =INDEX(Parameters!$G$5:$G$689,MATCH(Inputs!$B$4&"|IR|"&"delta_tenor_corr"&"|"&$A8&"|"&D$7,Parameters!$A$5:$A$689,0)) -> 0.65 | E8: =INDEX(Parameters!$G$5:$G$689,MATCH(Inputs!$B$4&"|IR|"&"delta_tenor_corr"&"|"&$A8&"|"&E$7,Parameters!$A$5:$A$689,0)) -> 0.54 | F8: =INDEX(Parameters!$G$5:$G$689,MATCH(Inputs!$B$4&"|IR|"&"delta_tenor_corr"&"|"&$A8&"|"&F$7,Parameters!$A$5:$A$689,0)) -> 0.4 | G8: =INDEX(Parameters!$G$5:$G$689,MATCH(Inputs!$B$4&"|IR|"&"delta_tenor_corr"&"|"&$A8&"|"&G$7,Parameters!$A$5:$A$689,0)) -> 0.29 | H8: =INDEX(Parameters!$G$5:$G$689,MATCH(Inputs!$B$4&"|IR|"&"delta_tenor_corr"&"|"&$A8&"|"&H$7,Parameters!$A$5:$A$689,0)) -> 0.25 | I8: =INDEX(Parameters!$G$5:$G$689,MATCH(Inputs!$B$4&"|IR|"&"delta_tenor_corr"&"|"&$A8&"|"&I$7,Parameters!$A$5:$A$689,0)) -> 0.22 | ... M8: =INDEX(Parameters!$G$5:$G$689,MATCH(Inputs!$B$4&"|IR|"&"delta_tenor_corr"&"|"&$A8&"|"&M$7,Parameters!$A$5:$A$689,0)) -> 0.14
A9: =Inputs!$C$14 -> 1m | B9: =INDEX(Parameters!$G$5:$G$689,MATCH(Inputs!$B$4&"|IR|"&"delta_tenor_corr"&"|"&$A9&"|"&B$7,Parameters!$A$5:$A$689,0)) -> 0.74 | C9: =INDEX(Parameters!$G$5:$G$689,MATCH(Inputs!$B$4&"|IR|"&"delta_tenor_corr"&"|"&$A9&"|"&C$7,Parameters!$A$5:$A$689,0)) -> 1 | D9: =INDEX(Parameters!$G$5:$G$689,MATCH(Inputs!$B$4&"|IR|"&"delta_tenor_corr"&"|"&$A9&"|"&D$7,Parameters!$A$5:$A$689,0)) -> 0.85 | E9: =INDEX(Parameters!$G$5:$G$689,MATCH(Inputs!$B$4&"|IR|"&"delta_tenor_corr"&"|"&$A9&"|"&E$7,Parameters!$A$5:$A$689,0)) -> 0.72 | F9: =INDEX(Parameters!$G$5:$G$689,MATCH(Inputs!$B$4&"|IR|"&"delta_tenor_corr"&"|"&$A9&"|"&F$7,Parameters!$A$5:$A$689,0)) -> 0.5 | G9: =INDEX(Parameters!$G$5:$G$689,MATCH(Inputs!$B$4&"|IR|"&"delta_tenor_corr"&"|"&$A9&"|"&G$7,Parameters!$A$5:$A$689,0)) -> 0.36 | H9: =INDEX(Parameters!$G$5:$G$689,MATCH(Inputs!$B$4&"|IR|"&"delta_tenor_corr"&"|"&$A9&"|"&H$7,Parameters!$A$5:$A$689,0)) -> 0.3 | I9: =INDEX(Parameters!$G$5:$G$689,MATCH(Inputs!$B$4&"|IR|"&"delta_tenor_corr"&"|"&$A9&"|"&I$7,Parameters!$A$5:$A$689,0)) -> 0.25 | ... M9: =INDEX(Parameters!$G$5:$G$689,MATCH(Inputs!$B$4&"|IR|"&"delta_tenor_corr"&"|"&$A9&"|"&M$7,Parameters!$A$5:$A$689,0)) -> 0.14
A10: =Inputs!$D$14 -> 3m | B10: =INDEX(Parameters!$G$5:$G$689,MATCH(Inputs!$B$4&"|IR|"&"delta_tenor_corr"&"|"&$A10&"|"&B$7,Parameters!$A$5:$A$689,0)) -> 0.65 | C10: =INDEX(Parameters!$G$5:$G$689,MATCH(Inputs!$B$4&"|IR|"&"delta_tenor_corr"&"|"&$A10&"|"&C$7,Parameters!$A$5:$A$689,0)) -> 0.85 | D10: =INDEX(Parameters!$G$5:$G$689,MATCH(Inputs!$B$4&"|IR|"&"delta_tenor_corr"&"|"&$A10&"|"&D$7,Parameters!$A$5:$A$689,0)) -> 1 | E10: =INDEX(Parameters!$G$5:$G$689,MATCH(Inputs!$B$4&"|IR|"&"delta_tenor_corr"&"|"&$A10&"|"&E$7,Parameters!$A$5:$A$689,0)) -> 0.9 | F10: =INDEX(Parameters!$G$5:$G$689,MATCH(Inputs!$B$4&"|IR|"&"delta_tenor_corr"&"|"&$A10&"|"&F$7,Parameters!$A$5:$A$689,0)) -> 0.69 | G10: =INDEX(Parameters!$G$5:$G$689,MATCH(Inputs!$B$4&"|IR|"&"delta_tenor_corr"&"|"&$A10&"|"&G$7,Parameters!$A$5:$A$689,0)) -> 0.53 | H10: =INDEX(Parameters!$G$5:$G$689,MATCH(Inputs!$B$4&"|IR|"&"delta_tenor_corr"&"|"&$A10&"|"&H$7,Parameters!$A$5:$A$689,0)) -> 0.46 | I10: =INDEX(Parameters!$G$5:$G$689,MATCH(Inputs!$B$4&"|IR|"&"delta_tenor_corr"&"|"&$A10&"|"&I$7,Parameters!$A$5:$A$689,0)) -> 0.4 | ... M10: =INDEX(Parameters!$G$5:$G$689,MATCH(Inputs!$B$4&"|IR|"&"delta_tenor_corr"&"|"&$A10&"|"&M$7,Parameters!$A$5:$A$689,0)) -> 0.25
A11: =Inputs!$E$14 -> 6m | B11: =INDEX(Parameters!$G$5:$G$689,MATCH(Inputs!$B$4&"|IR|"&"delta_tenor_corr"&"|"&$A11&"|"&B$7,Parameters!$A$5:$A$689,0)) -> 0.54 | C11: =INDEX(Parameters!$G$5:$G$689,MATCH(Inputs!$B$4&"|IR|"&"delta_tenor_corr"&"|"&$A11&"|"&C$7,Parameters!$A$5:$A$689,0)) -> 0.72 | D11: =INDEX(Parameters!$G$5:$G$689,MATCH(Inputs!$B$4&"|IR|"&"delta_tenor_corr"&"|"&$A11&"|"&D$7,Parameters!$A$5:$A$689,0)) -> 0.9 | E11: =INDEX(Parameters!$G$5:$G$689,MATCH(Inputs!$B$4&"|IR|"&"delta_tenor_corr"&"|"&$A11&"|"&E$7,Parameters!$A$5:$A$689,0)) -> 1 | F11: =INDEX(Parameters!$G$5:$G$689,MATCH(Inputs!$B$4&"|IR|"&"delta_tenor_corr"&"|"&$A11&"|"&F$7,Parameters!$A$5:$A$689,0)) -> 0.86 | G11: =INDEX(Parameters!$G$5:$G$689,MATCH(Inputs!$B$4&"|IR|"&"delta_tenor_corr"&"|"&$A11&"|"&G$7,Parameters!$A$5:$A$689,0)) -> 0.73 | H11: =INDEX(Parameters!$G$5:$G$689,MATCH(Inputs!$B$4&"|IR|"&"delta_tenor_corr"&"|"&$A11&"|"&H$7,Parameters!$A$5:$A$689,0)) -> 0.65 | I11: =INDEX(Parameters!$G$5:$G$689,MATCH(Inputs!$B$4&"|IR|"&"delta_tenor_corr"&"|"&$A11&"|"&I$7,Parameters!$A$5:$A$689,0)) -> 0.58 | ... M11: =INDEX(Parameters!$G$5:$G$689,MATCH(Inputs!$B$4&"|IR|"&"delta_tenor_corr"&"|"&$A11&"|"&M$7,Parameters!$A$5:$A$689,0)) -> 0.42
A12: =Inputs!$F$14 -> 1y | B12: =INDEX(Parameters!$G$5:$G$689,MATCH(Inputs!$B$4&"|IR|"&"delta_tenor_corr"&"|"&$A12&"|"&B$7,Parameters!$A$5:$A$689,0)) -> 0.4 | C12: =INDEX(Parameters!$G$5:$G$689,MATCH(Inputs!$B$4&"|IR|"&"delta_tenor_corr"&"|"&$A12&"|"&C$7,Parameters!$A$5:$A$689,0)) -> 0.5 | D12: =INDEX(Parameters!$G$5:$G$689,MATCH(Inputs!$B$4&"|IR|"&"delta_tenor_corr"&"|"&$A12&"|"&D$7,Parameters!$A$5:$A$689,0)) -> 0.69 | E12: =INDEX(Parameters!$G$5:$G$689,MATCH(Inputs!$B$4&"|IR|"&"delta_tenor_corr"&"|"&$A12&"|"&E$7,Parameters!$A$5:$A$689,0)) -> 0.86 | F12: =INDEX(Parameters!$G$5:$G$689,MATCH(Inputs!$B$4&"|IR|"&"delta_tenor_corr"&"|"&$A12&"|"&F$7,Parameters!$A$5:$A$689,0)) -> 1 | G12: =INDEX(Parameters!$G$5:$G$689,MATCH(Inputs!$B$4&"|IR|"&"delta_tenor_corr"&"|"&$A12&"|"&G$7,Parameters!$A$5:$A$689,0)) -> 0.94 | H12: =INDEX(Parameters!$G$5:$G$689,MATCH(Inputs!$B$4&"|IR|"&"delta_tenor_corr"&"|"&$A12&"|"&H$7,Parameters!$A$5:$A$689,0)) -> 0.87 | I12: =INDEX(Parameters!$G$5:$G$689,MATCH(Inputs!$B$4&"|IR|"&"delta_tenor_corr"&"|"&$A12&"|"&I$7,Parameters!$A$5:$A$689,0)) -> 0.81 | ... M12: =INDEX(Parameters!$G$5:$G$689,MATCH(Inputs!$B$4&"|IR|"&"delta_tenor_corr"&"|"&$A12&"|"&M$7,Parameters!$A$5:$A$689,0)) -> 0.63
A13: =Inputs!$G$14 -> 2y | B13: =INDEX(Parameters!$G$5:$G$689,MATCH(Inputs!$B$4&"|IR|"&"delta_tenor_corr"&"|"&$A13&"|"&B$7,Parameters!$A$5:$A$689,0)) -> 0.29 | C13: =INDEX(Parameters!$G$5:$G$689,MATCH(Inputs!$B$4&"|IR|"&"delta_tenor_corr"&"|"&$A13&"|"&C$7,Parameters!$A$5:$A$689,0)) -> 0.36 | D13: =INDEX(Parameters!$G$5:$G$689,MATCH(Inputs!$B$4&"|IR|"&"delta_tenor_corr"&"|"&$A13&"|"&D$7,Parameters!$A$5:$A$689,0)) -> 0.53 | E13: =INDEX(Parameters!$G$5:$G$689,MATCH(Inputs!$B$4&"|IR|"&"delta_tenor_corr"&"|"&$A13&"|"&E$7,Parameters!$A$5:$A$689,0)) -> 0.73 | F13: =INDEX(Parameters!$G$5:$G$689,MATCH(Inputs!$B$4&"|IR|"&"delta_tenor_corr"&"|"&$A13&"|"&F$7,Parameters!$A$5:$A$689,0)) -> 0.94 | G13: =INDEX(Parameters!$G$5:$G$689,MATCH(Inputs!$B$4&"|IR|"&"delta_tenor_corr"&"|"&$A13&"|"&G$7,Parameters!$A$5:$A$689,0)) -> 1 | H13: =INDEX(Parameters!$G$5:$G$689,MATCH(Inputs!$B$4&"|IR|"&"delta_tenor_corr"&"|"&$A13&"|"&H$7,Parameters!$A$5:$A$689,0)) -> 0.97 | I13: =INDEX(Parameters!$G$5:$G$689,MATCH(Inputs!$B$4&"|IR|"&"delta_tenor_corr"&"|"&$A13&"|"&I$7,Parameters!$A$5:$A$689,0)) -> 0.92 | ... M13: =INDEX(Parameters!$G$5:$G$689,MATCH(Inputs!$B$4&"|IR|"&"delta_tenor_corr"&"|"&$A13&"|"&M$7,Parameters!$A$5:$A$689,0)) -> 0.76
